---
title: "[C++] try-catch, throw 예외 처리"
excerpt: "예외 처리 방법인 try-catch에 대해 알아보자"

categories:
  - Cpp
tags:
  - [Cpp, exception]

toc : true
toc_sticky: true

last_modified_at: 2021-07-31
---

<mark style="background-color: #3e3e3e; color: #94EC81;">예외 처리</mark>(exception handling)란 프로그램 실행 도중에 일어나는   
비정상적인 예외(exception)를 처리하는 것을 말한다.

예외는 기본 자료형(`int`, `double`, ...)뿐만 아니라 객체(`Object`)도 가능하다.

C++ 에서는 <mark style="background-color: #3e3e3e; color: orange;">try-catch</mark>라는 예외 처리 방법을 제공한다.

```cpp
try {
  if (condition) throw A;
} catch (A) {
  //  code
}
```

<mark style="background-color: #3e3e3e; color: orange;">try-catch</mark>가 실행되는 과정은 아래와 같다.

* try의 조건을 만족하는 예외가 발생하면, A라는 예외를 던진다.
* catch에서 A를 받아 code를 실행한다.

## try-catch 사용

간단하게 예를 들어보자.

```cpp
int main()
{
  double num1, num2;
  std::cin >> num1 >> num2;

  try
  {
    if (num2 == 0) {
      throw "num2 is zero";
    } else {
      std::cout << num1 / num2 << std::endl;
    }
  }
  catch(const char* e)
  {
    std::cout << e << std::endl;
    std::cout << "분모는 0 이 될 수 없다." << std::endl;
  }
}


//  1 2
//  0.5

//  2 0
//  num2 is zero
//  분모는 0 이 될 수 없다.
```

* 만약 분모가 0이 되면 `num is zero`라는 문자열을 던지도록 했다.   
던진 문자열을 `catch`에서 받아 처리한다.

___

만약 어떤 예외든 잡으려면 아래와 같이 작성할 수 있다.

```cpp
catch(...) {
  //  code 
}
```

이 catch는 던져지는 모든 예외를 받을 수 있다.

___

객체의 처리도 가능하다.

```cpp
class Parent
{
public:
  ~Parent() {}
};

class Child : public Parent
{};

int main()
{
  double num1, num2;
  std::cin >> num1 >> num2;

  try
  {
    if (num2 == 0) {
      throw Child();
    } else {
      std::cout << num1 / num2 << std::endl;
    }
  }
  catch(Parent &)
  {
    std::cout << "예외" << std::endl;
  }
}


//  3 0
//  예외
```

* 클래스의 상속 개념으로 부모 클래스의 자료형으로   
자식 클래스 객체를 받는것이 가능하다.

___

`catch`는 여러 가지로 작성할 수 있다.   
하지만 `catch`의 파라미터에 2개 이상 적합하다면   
먼저 정의된 `catch`의 구문이 실행된다.

```cpp
class Parent
{
public:
  ~Parent() {}
};

class Child : public Parent
{};

int main()
{
  double num1, num2;
  std::cin >> num1 >> num2;

  try
  {
    if (num2 == 0) {
      throw Child();
    } else {
      std::cout << num1 / num2 << std::endl;
    }
  }
  
  catch(Parent &)
  {
    std::cout << "Parent catch" << std::endl;
  }
  
  catch(Child &)
  {
    std::cout << "Child catch" << std::endl;
  }
}


//  3 0
//  Parent catch
```

* `Child`클래스를 받는 `catch`가 있음에도   
`Parent`클래스를 받는 `catch`가 먼저 실행되는 것을 볼 수 있다.

때문에 `catch`를 작성할 때에는 좀 더 구체적인 `catch`를 먼저 작성해 주는 것이 좋다.

## 함수의 예외 처리

`try`가 아닌 함수에서도 예외를 던질 수 있다.

```cpp
class Parent
{
public:
  ~Parent() {}
};

class Child : public Parent
{};

void func()
{
  throw Child();
}

int main()
{
  try
  {
    func();
  }
  catch (Child &)
  {
    std::cout << "예외" << std::endl;
  }
}


//  예외
```

`try`에서 `func`함수를 실행하고, `func`함수에서 예외를 던진다.   
하지만 `func`에는 예외를 받는 `catch` 구문이 없어 처리할 수가 없다.

이때 던져진 예외는 `func`함수가 호출된 영역으로 전달된다.   
따라서 `try`의 위치로 전달된 뒤에 `main`함수의 `catch`에서 예외를 잡아낸다.

이렇게 호출된 영역으로 예외가 전달되는 현상을 <mark style="background-color: #3e3e3e; color: #94EC81;">스택 해제</mark>라고 한다.

## 스택 해제 (stack unwinding)

```cpp
void func4()
{
  throw 0;
  std::cout << "func4" << std::endl;
}

void func3()
{
  func4();
  std::cout << "func3" << std::endl;
}
void func2() 
{
  func3();
  std::cout << "func2" << std::endl;
}
void func4()
{
  func2();
  std::cout << "func1" << std::endl;
}

int main()
{
  try
  {
    func1();
  }
  catch(int &)
  {
    std::cout << "예외" << std::endl;
  }
}


//  예외
```

* `main`함수에서 연속적으로 함수가 호출되어 `func4`까지 도달하여 예외를 던지고,   
던져진 예외가 호출된 영역으로 전달되는 현상이 일어난다.   
다시 `main`함수의 처음 호출된 영역까지 예외가 전달되고,   
`catch`에서 예외를 처리하게 된다.

문제는 재귀 함수의 형태처럼 호출된 영역으로 돌아가는데,   
각 함수에 정의된 문자출력 구문이 실행되지 않았다는 것이다.

이러한 이유는 함수가 호출될 때 함수의 스택이 생성되는데,   
예외 데이터는 호출된 영역으로 전달될 때 자신과 자신을 호출한 함수의 스택을   
모두 해제한 뒤에 돌아가기 때문이다.

이것을 <mark style="background-color: #3e3e3e; color: #94EC81;">스택 해제</mark>라고 한다.

___

해제되는 현상을 클래스 소멸자를 통해 확인할 수 있다.

```cpp
class Test
{
  std::string msg_;
public:
  Test(const std::string msg) : msg_(msg)
  {}
  ~Test()
  {
    std::cout << msg_ << std::endl;
  }
};

void func4()
{
  Test t4("func4");
  throw 0;
}

void func3() 
{
  Test t3("func3");
  func4();
}
void func2() 
{
  Test t2("func2");
  func3();
}
void func1()
{
  Test t1("func1");
  func2();
}

int main()
{
  try
  {
    func1();
  }
  catch(int &)
  {
    std::cout << "예외" << std::endl;
  }
}


//  func4
//  func3
//  func2
//  func1
//  예외
```

* 각 함수에 선언된 객체가 스택 해제로 인해 소멸된다.

## rethrow

던져진 예외를 다시 던지는 것이 가능하다.

```cpp
void func2()
{
  throw 10;
}

void func1()
{
  try
  {
    func2();
  }
  catch(int exception)
  {
    std::cout << "func1 catch " << exception << std::endl;
    throw;
  }
}

int main()
{
  try
  {
    func1();
    std::cout << "main" << std::endl;
  }
  catch(int exception)
  {
    std::cout << "main catch " << exception << std::endl;
  }
}

//  func1 catch 10
//  main catch 10
```

* `func2`에서 예외를 던지고 던저진 예외가 `func1`의 `catch`에서 처리된다.   
하지만 다시 `throw`로 인해 예외를 던지고 던져진 예외를 `main`의 `catch`에서 처리한다.

위와 같이 다시 던져주는 `throw`는 예외를 명시하지 않고 명령어만으로 던져줄 수 있다.   
(위에서는 throw exception 이라고 적어줄 수도 있다.)